Workbook

Sheet Overview
B2: Data Cleaning – Before & After
B3: Sample portfolio file by Yousef Alkhateeb – all names, phones and emails are fictional.
B5: The task | C5: A raw beneficiary list exported from several forms: duplicates, mixed name cases, 17 spellings of 5 cities, 5 phone formats, 5 date formats and text inside number columns.
B6: The result | C6: One clean, de-duplicated table that can be filtered, counted and imported into any system.
B7: Sheets | C7: 1. Before (Raw) – the data as received 2. After (Clean) – the cleaned table with a Data Check column 3. Cleaning Log – every fix, with live counts
B8: Tools | C8: Microsoft Excel: TRIM/PROPER, Find & Replace, Text to Columns, Remove Duplicates, data validation, formulas, conditional formatting.
B9: Turnaround | C9: A file like this (≈50 rows) is cleaned within a few hours; thousands of rows within 1–3 days.

Sheet 1. Before (Raw)
A1: Full Name | B1: City | C1: Phone | D1: Registration Date | E1: Family Members | F1: Program | G1: Email
A2: Asma Nasser | D2: 16 August 2026 | E2: 1 persons | F2: Food parcel | G2: asma.nasser@example.com
A3: YAHYA HADDAD | B3: Rafah | C3: +970 594 464 264 | D3: 10/08/2026 | E3: 6 persons | F3: water voucher | G3: yahya.haddad@example.com
A4: tariq darwish | B4: nuseirat | C4: 00970592959077 | D4: 26/09/2026 | E4: 9 | F4: Cash assistance | G4: TARIQ.DARWISH@EXAMPLE.COM
A5: DINA SHAHEEN | B5: Rafah | C5: 597971464 | D5: 01/08/2026 | E5: 3 | F5: Cash assistance | G5: dina.shaheen@example.com
A6: Noor Hassan | B6: Khanyounis | C6: +970 592 280 718 | D6: 19 September 2026 | E6: 8 | F6: Food parcel | G6: noor.hassan@example.com
A7: Lina Qasem | B7: Gaza | D7: 2026-09-09 | E7: 4 | F7: Cash assistance | G7: lina.qasem@example.com
A8: TARIQ DARWISH | B8: nuseirat | C8: 00970592959077 | D8: 26/09/2026 | E8: 9 | F8: Cash assistance | G8: TARIQ.DARWISH@EXAMPLE.COM
A9: reem hamdan | B9: RAFAH | C9: 0596251262 | D9: 2026-08-19 | E9: 2 | F9: cash assistance | G9: reem.hamdan@example.com
A10: Fadi Mansour | B10: Deir Al Balah | D10: 11/09/2026 | E10: 9 | F10: cash assistance | G10: fadi.mansour@example.com
A11: Huda Saleh | B11: nuseirat | D11: 24/09/2026 | E11: 8 | F11: Cash assistance | G11: HUDA.SALEH@EXAMPLE.COM
A12: Aya Nasser | C12: 00970592278261 | D12: 16/09/2026 | E12: 1 persons | F12: hygiene kit | G12: aya.nasser@example.com
A13: ZIAD HAMDAN | B13: rafah | C13: +970 591 481 272 | D13: 04.09.2026 | E13: 1 | F13: Food parcel | G13: ziad.hamdan@example.com
A14: Reem Odeh | B14: rafah | C14: 00970598656506 | D14: 21 August 2026 | E14: 8 | F14: food parcel | G14: reem.odeh@example.com
A15: Fadi Shaheen | B15: Deir al-Balah | C15: 0599-441-824 | D15: 2026-09-18 | E15: 9 persons | F15: Water voucher | G15: FADI.SHAHEEN@EXAMPLE.COM
A16: ZIAD NAJJAR | B16: RAFAH | C16: 0592741281 | D16: 21 September 2026 | E16: 8 | F16: Cash assistance | G16: ziad.najjar@example.com
A17: AYA NAJJAR | B17: Gaza | C17: +970 599 176 756 | D17: 19/08/2026 | E17: 9 | F17: Water voucher | G17: AYA.NAJJAR@EXAMPLE.COM
A18: Sami Hamdan | B18: rafah | D18: 26-Aug-26 | E18: 2 | F18: cash assistance | G18: sami.hamdan@example.com
A19: Reem Nasser | B19: Khan Younis | C19: 590749078 | D19: 06/09/2026 | E19: 8 persons | F19: water voucher | G19: REEM.NASSER@EXAMPLE.COM
A20: SAMI NAJJAR | B20: deir el-balah | C20: 0597479146 | D20: 07/09/2026 | E20: 4 | F20: Hygiene kit | G20: sami.najjar@example.com
A21: yahya abed | B21: GAZA | C21: 0595482348 | D21: 08/29/2026 | E21: 4 | F21: food parcel | G21: yahya.abed@example.com
A22: Fadi Hassan | B22: Khan Younis | C22: 0598-479-324 | D22: 14-Aug-26 | E22: 9 | F22: Food parcel | G22: FADI.HASSAN@EXAMPLE.COM
A23: noor khalil | B23: gaza | C23: 597542182 | D23: 10 August 2026 | E23: 11 | F23: Food parcel | G23: noor.khalil@example.com
A24: Nader Qasem | B24: Gaza City | C24: +970 595 729 908 | D24: 08-Aug-26 | E24: 2 persons | F24: Food parcel | G24: NADER.QASEM@EXAMPLE.COM
A25: wael shaheen | B25: rafah | D25: 2026-08-06 | E25: 8 | F25: Cash assistance | G25: wael.shaheen@example.com
A26: Fadi Shaheen | B26: Deir al-Balah | C26: 0599-441-824 | D26: 2026-09-18 | E26: 9 persons | F26: Water voucher | G26: FADI.SHAHEEN@EXAMPLE.COM
A27: amal matar | B27: nuseirat | C27: 0595-314-301 | D27: 13 August 2026 | E27: 10 | F27: food parcel | G27: amal.matar@example.com
A28: reem khalil | B28: Nusirat | C28: +970 595 723 241 | D28: 22 August 2026 | E28: 10 | F28: Water voucher | G28: reem.khalil@example.com
A29: Hani Najjar | B29: deir el-balah | C29: 0596801133 | D29: 2026-08-19 | E29: 1 | F29: water voucher | G29: hani.najjar@example.com
A30: Huda Matar | B30: Khanyounis | D30: 10/09/2026 | E30: 2 | F30: hygiene kit | G30: huda.matar@example.com
A31: Sami Najjar | B31: deir el-balah | C31: 0597479146 | D31: 07/09/2026 | E31: 4 | F31: Hygiene kit | G31: sami.najjar@example.com
A32: Wael Shaheen | B32: rafah | D32: 2026-08-06 | E32: 8 | F32: Cash assistance | G32: wael.shaheen@example.com
A33: REEM QASEM | B33: Khanyounis | C33: 0599-698-951 | D33: 2026-08-07 | E33: 6 | F33: Food parcel | G33: reem.qasem@example.com
A34: Omar Hamdan | B34: Gaza City | C34: +970 590 938 186 | D34: 02-Aug-26 | E34: 9 | F34: Hygiene kit | G34: omar.hamdan@example.com
A35: Yahya Matar | B35: Deir Al Balah | D35: 23-Aug-26 | E35: 8 | F35: cash assistance | G35: yahya.matar@example.com
A36: Khaled Nasser | B36: gaza | D36: 30/09/2026 | E36: 1 | F36: Cash assistance | G36: khaled.nasser@example.com
A37: Asma Barakat | B37: Dair al Balah | C37: +970 593 129 353 | D37: 2026-09-22 | E37: 4 | F37: Cash assistance | G37: asma.barakat@example.com
A38: AMAL ODEH | B38: gaza | C38: 0599-515-949 | D38: 06/09/2026 | E38: 4 | F38: Food parcel | G38: amal.odeh@example.com
A39: Fadi Hassan | B39: Khan Younis | C39: 0598-479-324 | D39: 14-Aug-26 | E39: 9 | F39: Food parcel | G39: FADI.HASSAN@EXAMPLE.COM
A40: Khaled Hamdan | B40: Dair al Balah | C40: 0595-876-314 | D40: 07-Aug-26 | E40: 8 | F40: Hygiene kit | G40: khaled.hamdan@example.com
...

Sheet 2. After (Clean)
A1: Record ID | B1: Full Name | C1: City | D1: Phone (+970) | E1: Registration Date | F1: Family Members | G1: Program | H1: Email | I1: Data Check
A2: BEN-2001 | B2: Dina Shaheen | C2: Rafah | D2: +970 597 971 464 | E2: 46235 | F2: 3 | G2: Cash assistance | H2: dina.shaheen@example.com | I2: =IF(COUNTBLANK(B2:H2)=0,"Complete","Missing: "&IF(C2="","City ","")&IF(D2="","Phone","")) -> Complete
A3: BEN-2002 | B3: Omar Hamdan | C3: Gaza | D3: +970 590 938 186 | E3: 46236 | F3: 9 | G3: Hygiene kit | H3: omar.hamdan@example.com | I3: =IF(COUNTBLANK(B3:H3)=0,"Complete","Missing: "&IF(C3="","City ","")&IF(D3="","Phone","")) -> Complete
A4: BEN-2003 | B4: Wael Shaheen | C4: Rafah | E4: 46240 | F4: 8 | G4: Cash assistance | H4: wael.shaheen@example.com | I4: =IF(COUNTBLANK(B4:H4)=0,"Complete","Missing: "&IF(C4="","City ","")&IF(D4="","Phone","")) -> Missing: Phone
A5: BEN-2004 | B5: Reem Qasem | C5: Khan Younis | D5: +970 599 698 951 | E5: 46241 | F5: 6 | G5: Food parcel | H5: reem.qasem@example.com | I5: =IF(COUNTBLANK(B5:H5)=0,"Complete","Missing: "&IF(C5="","City ","")&IF(D5="","Phone","")) -> Complete
A6: BEN-2005 | B6: Khaled Hamdan | C6: Deir al-Balah | D6: +970 595 876 314 | E6: 46241 | F6: 8 | G6: Hygiene kit | H6: khaled.hamdan@example.com | I6: =IF(COUNTBLANK(B6:H6)=0,"Complete","Missing: "&IF(C6="","City ","")&IF(D6="","Phone","")) -> Complete
A7: BEN-2006 | B7: Nader Qasem | C7: Gaza | D7: +970 595 729 908 | E7: 46242 | F7: 2 | G7: Food parcel | H7: nader.qasem@example.com | I7: =IF(COUNTBLANK(B7:H7)=0,"Complete","Missing: "&IF(C7="","City ","")&IF(D7="","Phone","")) -> Complete
A8: BEN-2007 | B8: Yahya Haddad | C8: Rafah | D8: +970 594 464 264 | E8: 46244 | F8: 6 | G8: Water voucher | H8: yahya.haddad@example.com | I8: =IF(COUNTBLANK(B8:H8)=0,"Complete","Missing: "&IF(C8="","City ","")&IF(D8="","Phone","")) -> Complete
A9: BEN-2008 | B9: Noor Khalil | C9: Gaza | D9: +970 597 542 182 | E9: 46244 | F9: 11 | G9: Food parcel | H9: noor.khalil@example.com | I9: =IF(COUNTBLANK(B9:H9)=0,"Complete","Missing: "&IF(C9="","City ","")&IF(D9="","Phone","")) -> Complete
A10: BEN-2009 | B10: Rana Hassan | C10: Deir al-Balah | D10: +970 596 660 559 | E10: 46244 | F10: 10 | G10: Cash assistance | H10: rana.hassan@example.com | I10: =IF(COUNTBLANK(B10:H10)=0,"Complete","Missing: "&IF(C10="","City ","")&IF(D10="","Phone","")) -> Complete
A11: BEN-2010 | B11: Amal Matar | C11: Nuseirat | D11: +970 595 314 301 | E11: 46247 | F11: 10 | G11: Food parcel | H11: amal.matar@example.com | I11: =IF(COUNTBLANK(B11:H11)=0,"Complete","Missing: "&IF(C11="","City ","")&IF(D11="","Phone","")) -> Complete
A12: BEN-2011 | B12: Fadi Hassan | C12: Khan Younis | D12: +970 598 479 324 | E12: 46248 | F12: 9 | G12: Food parcel | H12: fadi.hassan@example.com | I12: =IF(COUNTBLANK(B12:H12)=0,"Complete","Missing: "&IF(C12="","City ","")&IF(D12="","Phone","")) -> Complete
A13: BEN-2012 | B13: Asma Nasser | E13: 46250 | F13: 1 | G13: Food parcel | H13: asma.nasser@example.com | I13: =IF(COUNTBLANK(B13:H13)=0,"Complete","Missing: "&IF(C13="","City ","")&IF(D13="","Phone","")) -> Missing: City Phone
A14: BEN-2013 | B14: Reem Hamdan | C14: Rafah | D14: +970 596 251 262 | E14: 46253 | F14: 2 | G14: Cash assistance | H14: reem.hamdan@example.com | I14: =IF(COUNTBLANK(B14:H14)=0,"Complete","Missing: "&IF(C14="","City ","")&IF(D14="","Phone","")) -> Complete
A15: BEN-2014 | B15: Aya Najjar | C15: Gaza | D15: +970 599 176 756 | E15: 46253 | F15: 9 | G15: Water voucher | H15: aya.najjar@example.com | I15: =IF(COUNTBLANK(B15:H15)=0,"Complete","Missing: "&IF(C15="","City ","")&IF(D15="","Phone","")) -> Complete
A16: BEN-2015 | B16: Hani Najjar | C16: Deir al-Balah | D16: +970 596 801 133 | E16: 46253 | F16: 1 | G16: Water voucher | H16: hani.najjar@example.com | I16: =IF(COUNTBLANK(B16:H16)=0,"Complete","Missing: "&IF(C16="","City ","")&IF(D16="","Phone","")) -> Complete
A17: BEN-2016 | B17: Reem Odeh | C17: Rafah | D17: +970 598 656 506 | E17: 46255 | F17: 8 | G17: Food parcel | H17: reem.odeh@example.com | I17: =IF(COUNTBLANK(B17:H17)=0,"Complete","Missing: "&IF(C17="","City ","")&IF(D17="","Phone","")) -> Complete
A18: BEN-2017 | B18: Reem Khalil | C18: Nuseirat | D18: +970 595 723 241 | E18: 46256 | F18: 10 | G18: Water voucher | H18: reem.khalil@example.com | I18: =IF(COUNTBLANK(B18:H18)=0,"Complete","Missing: "&IF(C18="","City ","")&IF(D18="","Phone","")) -> Complete
A19: BEN-2018 | B19: Yahya Matar | C19: Deir al-Balah | E19: 46257 | F19: 8 | G19: Cash assistance | H19: yahya.matar@example.com | I19: =IF(COUNTBLANK(B19:H19)=0,"Complete","Missing: "&IF(C19="","City ","")&IF(D19="","Phone","")) -> Missing: Phone
A20: BEN-2019 | B20: Wael Awad | C20: Khan Younis | D20: +970 596 341 960 | E20: 46257 | F20: 2 | G20: Hygiene kit | H20: wael.awad@example.com | I20: =IF(COUNTBLANK(B20:H20)=0,"Complete","Missing: "&IF(C20="","City ","")&IF(D20="","Phone","")) -> Complete
A21: BEN-2020 | B21: Sami Hamdan | C21: Rafah | E21: 46260 | F21: 2 | G21: Cash assistance | H21: sami.hamdan@example.com | I21: =IF(COUNTBLANK(B21:H21)=0,"Complete","Missing: "&IF(C21="","City ","")&IF(D21="","Phone","")) -> Missing: Phone
A22: BEN-2021 | B22: Omar Shaheen | C22: Gaza | D22: +970 596 620 625 | E22: 46260 | F22: 3 | G22: Water voucher | H22: omar.shaheen@example.com | I22: =IF(COUNTBLANK(B22:H22)=0,"Complete","Missing: "&IF(C22="","City ","")&IF(D22="","Phone","")) -> Complete
A23: BEN-2022 | B23: Hiba Qasem | C23: Nuseirat | E23: 46262 | F23: 8 | G23: Water voucher | H23: hiba.qasem@example.com | I23: =IF(COUNTBLANK(B23:H23)=0,"Complete","Missing: "&IF(C23="","City ","")&IF(D23="","Phone","")) -> Missing: Phone
A24: BEN-2023 | B24: Yahya Abed | C24: Gaza | D24: +970 595 482 348 | E24: 46263 | F24: 4 | G24: Food parcel | H24: yahya.abed@example.com | I24: =IF(COUNTBLANK(B24:H24)=0,"Complete","Missing: "&IF(C24="","City ","")&IF(D24="","Phone","")) -> Complete
A25: BEN-2024 | B25: Omar Odeh | C25: Nuseirat | D25: +970 598 511 439 | E25: 46264 | F25: 7 | G25: Water voucher | H25: omar.odeh@example.com | I25: =IF(COUNTBLANK(B25:H25)=0,"Complete","Missing: "&IF(C25="","City ","")&IF(D25="","Phone","")) -> Complete
A26: BEN-2025 | B26: Ziad Hamdan | C26: Rafah | D26: +970 591 481 272 | E26: 46269 | F26: 1 | G26: Food parcel | H26: ziad.hamdan@example.com | I26: =IF(COUNTBLANK(B26:H26)=0,"Complete","Missing: "&IF(C26="","City ","")&IF(D26="","Phone","")) -> Complete
A27: BEN-2026 | B27: Fadi Hamdan | C27: Rafah | E27: 46269 | F27: 1 | G27: Water voucher | H27: fadi.hamdan@example.com | I27: =IF(COUNTBLANK(B27:H27)=0,"Complete","Missing: "&IF(C27="","City ","")&IF(D27="","Phone","")) -> Missing: Phone
A28: BEN-2027 | B28: Reem Nasser | C28: Khan Younis | D28: +970 590 749 078 | E28: 46271 | F28: 8 | G28: Water voucher | H28: reem.nasser@example.com | I28: =IF(COUNTBLANK(B28:H28)=0,"Complete","Missing: "&IF(C28="","City ","")&IF(D28="","Phone","")) -> Complete
A29: BEN-2028 | B29: Amal Odeh | C29: Gaza | D29: +970 599 515 949 | E29: 46271 | F29: 4 | G29: Food parcel | H29: amal.odeh@example.com | I29: =IF(COUNTBLANK(B29:H29)=0,"Complete","Missing: "&IF(C29="","City ","")&IF(D29="","Phone","")) -> Complete
A30: BEN-2029 | B30: Sami Najjar | C30: Deir al-Balah | D30: +970 597 479 146 | E30: 46272 | F30: 4 | G30: Hygiene kit | H30: sami.najjar@example.com | I30: =IF(COUNTBLANK(B30:H30)=0,"Complete","Missing: "&IF(C30="","City ","")&IF(D30="","Phone","")) -> Complete
A31: BEN-2030 | B31: Lina Qasem | C31: Gaza | E31: 46274 | F31: 4 | G31: Cash assistance | H31: lina.qasem@example.com | I31: =IF(COUNTBLANK(B31:H31)=0,"Complete","Missing: "&IF(C31="","City ","")&IF(D31="","Phone","")) -> Missing: Phone
A32: BEN-2031 | B32: Hani Shaheen | C32: Khan Younis | E32: 46274 | F32: 7 | G32: Hygiene kit | H32: hani.shaheen@example.com | I32: =IF(COUNTBLANK(B32:H32)=0,"Complete","Missing: "&IF(C32="","City ","")&IF(D32="","Phone","")) -> Missing: Phone
A33: BEN-2032 | B33: Huda Matar | C33: Khan Younis | E33: 46275 | F33: 2 | G33: Hygiene kit | H33: huda.matar@example.com | I33: =IF(COUNTBLANK(B33:H33)=0,"Complete","Missing: "&IF(C33="","City ","")&IF(D33="","Phone","")) -> Missing: Phone
A34: BEN-2033 | B34: Fadi Mansour | C34: Deir al-Balah | E34: 46276 | F34: 9 | G34: Cash assistance | H34: fadi.mansour@example.com | I34: =IF(COUNTBLANK(B34:H34)=0,"Complete","Missing: "&IF(C34="","City ","")&IF(D34="","Phone","")) -> Missing: Phone
A35: BEN-2034 | B35: Aya Nasser | D35: +970 592 278 261 | E35: 46281 | F35: 1 | G35: Hygiene kit | H35: aya.nasser@example.com | I35: =IF(COUNTBLANK(B35:H35)=0,"Complete","Missing: "&IF(C35="","City ","")&IF(D35="","Phone","")) -> Missing: City
A36: BEN-2035 | B36: Fadi Shaheen | C36: Deir al-Balah | D36: +970 599 441 824 | E36: 46283 | F36: 9 | G36: Water voucher | H36: fadi.shaheen@example.com | I36: =IF(COUNTBLANK(B36:H36)=0,"Complete","Missing: "&IF(C36="","City ","")&IF(D36="","Phone","")) -> Complete
A37: BEN-2036 | B37: Noor Hassan | C37: Khan Younis | D37: +970 592 280 718 | E37: 46284 | F37: 8 | G37: Food parcel | H37: noor.hassan@example.com | I37: =IF(COUNTBLANK(B37:H37)=0,"Complete","Missing: "&IF(C37="","City ","")&IF(D37="","Phone","")) -> Complete
A38: BEN-2037 | B38: Noor Abed | C38: Rafah | E38: 46284 | F38: 9 | G38: Cash assistance | H38: noor.abed@example.com | I38: =IF(COUNTBLANK(B38:H38)=0,"Complete","Missing: "&IF(C38="","City ","")&IF(D38="","Phone","")) -> Missing: Phone
A39: BEN-2038 | B39: Ziad Najjar | C39: Rafah | D39: +970 592 741 281 | E39: 46286 | F39: 8 | G39: Cash assistance | H39: ziad.najjar@example.com | I39: =IF(COUNTBLANK(B39:H39)=0,"Complete","Missing: "&IF(C39="","City ","")&IF(D39="","Phone","")) -> Complete
A40: BEN-2039 | B40: Hiba Abed | C40: Gaza | E40: 46286 | F40: 7 | G40: Hygiene kit | H40: hiba.abed@example.com | I40: =IF(COUNTBLANK(B40:H40)=0,"Complete","Missing: "&IF(C40="","City ","")&IF(D40="","Phone","")) -> Missing: Phone
...

Sheet 3. Cleaning Log
B2: What was fixed
B4: Check | C4: Result | D4: How it was handled
B5: Rows received (raw) | C5: =COUNTA('1. Before (Raw)'!A2:A53) -> 52 | D5: Original export, no changes.
B6: Duplicate records removed | C6: =COUNTA('1. Before (Raw)'!A2:A53)-COUNTA('2. After (Clean)'!A2:A46) -> 7 | D6: Same person entered twice with different spacing/case – kept one record.
B7: Clean, unique records | C7: =COUNTA('2. After (Clean)'!A2:A46) -> 45 | D7: Each record given a unique Record ID (BEN-xxxx).
B8: Names standardised | C8: =COUNTA('2. After (Clean)'!B2:B46) -> 45 | D8: Trimmed extra spaces, Proper Case (e.g. 'AHMAD HASSAN' → 'Ahmad Hassan').
B9: City spellings unified | C9: =COUNTA('2. After (Clean)'!C2:C46) -> 42 | D9: 17 spelling variants mapped to 5 standard city names.
B10: Phone numbers standardised | C10: =COUNTA('2. After (Clean)'!D2:D46) -> 31 | D10: All formats (00970…, 059-…, missing 0) converted to +970 5X XXX XXXX.
B11: Dates converted to real dates | C11: =COUNT('2. After (Clean)'!E2:E46) -> 45 | D11: 5 text formats incl. mixed day/month order (31/08/2026, 2026-08-31, 31-Aug-26 …) → real dates.
B12: Family size made numeric | C12: =COUNT('2. After (Clean)'!F2:F46) -> 45 | D12: Removed text such as '5 persons' so totals and averages work.
B13: Records still missing data | C13: =COUNTIF('2. After (Clean)'!I2:I46,"Missing*") -> 16 | D13: Flagged in the 'Data Check' column for follow-up – not guessed.
B14: Total individuals (clean data) | C14: =SUM('2. After (Clean)'!F2:F46) -> 262 | D14: Now possible because family size is numeric.
